Caused by: java.util.concurrent.ExecutionException: java.lang.RuntimeException: Error received from SDK harness for instruction 4: Traceback (most recent call last):
  File "/tmp/python-dist-656debec-6078-40fa-9e0a-08bcfd84c7f6/python-archives/env_3_7_f_1_13_2_t_d5cceed188a8aa2a5dbff6189ee5cf60bb416dfb022ad951caef306580066400.zip/env_3_7_f_1_13_2_t_d5cceed188a8aa2a5dbff6189ee5cf60bb416dfb022ad951caef306580066400/lib/python3.7/site-packages/apache_beam/runners/worker/sdk_worker.py", line 289, in _execute
    response = task()
  File "/tmp/python-dist-656debec-6078-40fa-9e0a-08bcfd84c7f6/python-archives/env_3_7_f_1_13_2_t_d5cceed188a8aa2a5dbff6189ee5cf60bb416dfb022ad951caef306580066400.zip/env_3_7_f_1_13_2_t_d5cceed188a8aa2a5dbff6189ee5cf60bb416dfb022ad951caef306580066400/lib/python3.7/site-packages/apache_beam/runners/worker/sdk_worker.py", line 362, in <lambda>
    lambda: self.create_worker().do_instruction(request), request)
  File "/tmp/python-dist-656debec-6078-40fa-9e0a-08bcfd84c7f6/python-archives/env_3_7_f_1_13_2_t_d5cceed188a8aa2a5dbff6189ee5cf60bb416dfb022ad951caef306580066400.zip/env_3_7_f_1_13_2_t_d5cceed188a8aa2a5dbff6189ee5cf60bb416dfb022ad951caef306580066400/lib/python3.7/site-packages/apache_beam/runners/worker/sdk_worker.py", line 607, in do_instruction
    getattr(request, request_type), request.instruction_id)
  File "/tmp/python-dist-656debec-6078-40fa-9e0a-08bcfd84c7f6/python-archives/env_3_7_f_1_13_2_t_d5cceed188a8aa2a5dbff6189ee5cf60bb416dfb022ad951caef306580066400.zip/env_3_7_f_1_13_2_t_d5cceed188a8aa2a5dbff6189ee5cf60bb416dfb022ad951caef306580066400/lib/python3.7/site-packages/apache_beam/runners/worker/sdk_worker.py", line 644, in process_bundle
    bundle_processor.process_bundle(instruction_id))
  File "/tmp/python-dist-656debec-6078-40fa-9e0a-08bcfd84c7f6/python-archives/env_3_7_f_1_13_2_t_d5cceed188a8aa2a5dbff6189ee5cf60bb416dfb022ad951caef306580066400.zip/env_3_7_f_1_13_2_t_d5cceed188a8aa2a5dbff6189ee5cf60bb416dfb022ad951caef306580066400/lib/python3.7/site-packages/apache_beam/runners/worker/bundle_processor.py", line 1000, in process_bundle
    element.data)
  File "/tmp/python-dist-656debec-6078-40fa-9e0a-08bcfd84c7f6/python-archives/env_3_7_f_1_13_2_t_d5cceed188a8aa2a5dbff6189ee5cf60bb416dfb022ad951caef306580066400.zip/env_3_7_f_1_13_2_t_d5cceed188a8aa2a5dbff6189ee5cf60bb416dfb022ad951caef306580066400/lib/python3.7/site-packages/apache_beam/runners/worker/bundle_processor.py", line 228, in process_encoded
    self.output(decoded_value)
  File "apache_beam/runners/worker/operations.py", line 357, in apache_beam.runners.worker.operations.Operation.output
  File "apache_beam/runners/worker/operations.py", line 359, in apache_beam.runners.worker.operations.Operation.output
  File "apache_beam/runners/worker/operations.py", line 221, in apache_beam.runners.worker.operations.SingletonConsumerSet.receive
  File "pyflink/fn_execution/beam/beam_operations_fast.pyx", line 71, in pyflink.fn_execution.beam.beam_operations_fast.FunctionOperation.process
  File "pyflink/fn_execution/beam/beam_operations_fast.pyx", line 85, in pyflink.fn_execution.beam.beam_operations_fast.FunctionOperation.process
  File "pyflink/fn_execution/coder_impl_fast.pyx", line 140, in pyflink.fn_execution.coder_impl_fast.DataStreamFlatMapCoderImpl.encode_to_stream
  File "/tmp/python-dist-656debec-6078-40fa-9e0a-08bcfd84c7f6/python-files/pyflink_machina_core.py/pyflink_machina_core.py", line 243, in flat_map
    for value in self._flat_map(row_dict):
  File "/tmp/python-dist-656debec-6078-40fa-9e0a-08bcfd84c7f6/python-files/pyflink_machina_core.py/pyflink_machina_core.py", line 239, in _flat_map
    for result_dict in self.main_generate_func(self, row_dict):
  File "/flink/usrlib/machina_pyflink_dryrun_m615.py", line 208, in main_func_m615
  File "/tmp/python-dist-656debec-6078-40fa-9e0a-08bcfd84c7f6/python-files/pyflink_machina_core.py/pyflink_machina_core.py", line 753, in predict
    model = self.model # get model, let it raise if failed
  File "/tmp/python-dist-656debec-6078-40fa-9e0a-08bcfd84c7f6/python-files/pyflink_machina_core.py/pyflink_machina_core.py", line 749, in model
    self._model = self.get_model()
  File "/tmp/python-dist-656debec-6078-40fa-9e0a-08bcfd84c7f6/python-files/pyflink_machina_core.py/pyflink_machina_core.py", line 742, in get_model
    model = self.load_model(self.model_run_id)
  File "/tmp/python-dist-656debec-6078-40fa-9e0a-08bcfd84c7f6/python-files/pyflink_machina_core.py/pyflink_machina_core.py", line 735, in load_model
    model = load_model("runs:/{}/model_pyfunc".format(run_id))
  File "/tmp/python-dist-656debec-6078-40fa-9e0a-08bcfd84c7f6/python-archives/env_3_7_f_1_13_2_t_d5cceed188a8aa2a5dbff6189ee5cf60bb416dfb022ad951caef306580066400.zip/env_3_7_f_1_13_2_t_d5cceed188a8aa2a5dbff6189ee5cf60bb416dfb022ad951caef306580066400/lib/python3.7/site-packages/mlflow/pyfunc/__init__.py", line 281, in load_model
    return load_pyfunc(model_uri, suppress_warnings)
  File "/tmp/python-dist-656debec-6078-40fa-9e0a-08bcfd84c7f6/python-archives/env_3_7_f_1_13_2_t_d5cceed188a8aa2a5dbff6189ee5cf60bb416dfb022ad951caef306580066400.zip/env_3_7_f_1_13_2_t_d5cceed188a8aa2a5dbff6189ee5cf60bb416dfb022ad951caef306580066400/lib/python3.7/site-packages/mlflow/utils/annotations.py", line 40, in deprecated_func
    return func(*args, **kwargs)
  File "/tmp/python-dist-656debec-6078-40fa-9e0a-08bcfd84c7f6/python-archives/env_3_7_f_1_13_2_t_d5cceed188a8aa2a5dbff6189ee5cf60bb416dfb022ad951caef306580066400.zip/env_3_7_f_1_13_2_t_d5cceed188a8aa2a5dbff6189ee5cf60bb416dfb022ad951caef306580066400/lib/python3.7/site-packages/mlflow/pyfunc/__init__.py", line 313, in load_pyfunc
    return importlib.import_module(conf[MAIN])._load_pyfunc(data_path)
  File "/tmp/python-dist-656debec-6078-40fa-9e0a-08bcfd84c7f6/python-archives/env_3_7_f_1_13_2_t_d5cceed188a8aa2a5dbff6189ee5cf60bb416dfb022ad951caef306580066400.zip/env_3_7_f_1_13_2_t_d5cceed188a8aa2a5dbff6189ee5cf60bb416dfb022ad951caef306580066400/lib/python3.7/site-packages/mlflow/pyfunc/model.py", line 223, in _load_pyfunc
    python_model.load_context(context=context)
  File "/mnt/disk4/yarn/usercache/chenxiaotian/appcache/application_1631785855448_9889/container_e15_1631785855448_9889_01_000002/tml-python-env/etc/ipython/profile_default/startup/12_mlflow_wrappers.py", line 34, in load_context
  File "/mnt/disk4/yarn/usercache/chenxiaotian/appcache/application_1631785855448_9889/container_e15_1631785855448_9889_01_000002/tml-python-env/etc/ipython/profile_default/startup/12_mlflow_wrappers.py", line 366, in load_model
  File "/tmp/python-dist-656debec-6078-40fa-9e0a-08bcfd84c7f6/python-archives/env_3_7_f_1_13_2_t_d5cceed188a8aa2a5dbff6189ee5cf60bb416dfb022ad951caef306580066400.zip/env_3_7_f_1_13_2_t_d5cceed188a8aa2a5dbff6189ee5cf60bb416dfb022ad951caef306580066400/lib/python3.7/site-packages/mlflow/pytorch/__init__.py", line 345, in load_model
    return _load_model(path=torch_model_artifacts_path, **kwargs)
  File "/tmp/python-dist-656debec-6078-40fa-9e0a-08bcfd84c7f6/python-archives/env_3_7_f_1_13_2_t_d5cceed188a8aa2a5dbff6189ee5cf60bb416dfb022ad951caef306580066400.zip/env_3_7_f_1_13_2_t_d5cceed188a8aa2a5dbff6189ee5cf60bb416dfb022ad951caef306580066400/lib/python3.7/site-packages/mlflow/pytorch/__init__.py", line 296, in _load_model
    return torch.load(model_path, **kwargs)
  File "/tmp/python-dist-656debec-6078-40fa-9e0a-08bcfd84c7f6/python-archives/env_3_7_f_1_13_2_t_d5cceed188a8aa2a5dbff6189ee5cf60bb416dfb022ad951caef306580066400.zip/env_3_7_f_1_13_2_t_d5cceed188a8aa2a5dbff6189ee5cf60bb416dfb022ad951caef306580066400/lib/python3.7/site-packages/torch/serialization.py", line 592, in load
    return _load(opened_zipfile, map_location, pickle_module, **pickle_load_args)
  File "/tmp/python-dist-656debec-6078-40fa-9e0a-08bcfd84c7f6/python-archives/env_3_7_f_1_13_2_t_d5cceed188a8aa2a5dbff6189ee5cf60bb416dfb022ad951caef306580066400.zip/env_3_7_f_1_13_2_t_d5cceed188a8aa2a5dbff6189ee5cf60bb416dfb022ad951caef306580066400/lib/python3.7/site-packages/torch/serialization.py", line 851, in _load
    result = unpickler.load()
ModuleNotFoundError: No module named 'all2graph.nn'